<?xml version="1.0"?>
<robot name="r2d2" xmlns:xacro="http://www.ros.org/wiki/xacro">

  <xacro:arg name="config_dir" default=""/>
  
  <link name="body">
    <inertial>
      <origin xyz="0 0 0" rpy="0 0 0"/>
      <mass value="3.14395"/>
      <inertia ixx="0.095329" ixy="0" ixz="0" iyy="0.381317" iyz="0" izz="0.476646"/>
    </inertial>
    <visual>
      <origin xyz="0 0 0" rpy="0 0 0"/>
      <geometry>
        <cylinder radius="0.3" length="0.6"/>
      </geometry>
      <material name="body_material">
        <color rgba="0.95 0.95 0.95 1"/>
      </material>
    </visual>
    <collision>
      <origin xyz="0 0 0.05" rpy="0 0 0"/>
      <geometry>
        <cylinder radius="0.3" length="0.7"/>
      </geometry>
    </collision>
  </link>

  <link name="left_wheel">
    <inertial>
      <origin xyz="0 0 0" rpy="0 0 0"/>
      <mass value="2"/>
      <inertia ixx="0.043333" ixy="0" ixz="0" iyy="0.043333" iyz="0" izz="0.08"/>
    </inertial>
    <visual>
      <origin xyz="0 0 0" rpy="0 0 0"/>
      <geometry>
        <cylinder radius="0.1" length="0.06"/>
      </geometry>
      <material name="wheel_material">
        <color rgba="0.2 0.2 0.2 1"/>
      </material>
    </visual>
    <collision>
      <geometry>
        <cylinder radius="0.1" length="0.06"/>
      </geometry>
      <surface>
        <friction>
          <ode>
            <mu>1.0</mu>
            <mu2>1.0</mu2>
          </ode>
        </friction>
      </surface>
    </collision>
  </link>

  <link name="right_wheel">
    <inertial>
      <origin xyz="0 0 0" rpy="0 0 0"/>
      <mass value="2"/>
      <inertia ixx="0.043333" ixy="0" ixz="0" iyy="0.043333" iyz="0" izz="0.08"/>
    </inertial>
    <visual>
      <geometry>
        <cylinder radius="0.1" length="0.06"/>
      </geometry>
      <material name="wheel_material">
        <color rgba="0.2 0.2 0.2 1"/>
      </material>
    </visual>
    <collision>
      <geometry>
        <cylinder radius="0.1" length="0.06"/>
      </geometry>
      <surface>
        <friction>
          <ode>
            <mu>1.0</mu>
            <mu2>1.0</mu2>
          </ode>
        </friction>
      </surface>
    </collision>
  </link>

  <link name="front_wheel">
    <inertial>
      <origin xyz="0 0 0" rpy="0 0 0"/>
      <mass value="1.0"/>
      <inertia ixx="0.01" ixy="0" ixz="0" iyy="0.01" iyz="0" izz="0.01"/>
    </inertial>
    <visual>
      <origin xyz="0 0 0" rpy="0 0 0"/>
      <geometry>
        <cylinder radius="0.08" length="0.04"/>
      </geometry>
      <material name="front_wheel_mat">
        <color rgba="0.2 0.2 0.2 1"/>
      </material>
    </visual>
    <collision>
      <geometry>
        <cylinder radius="0.08" length="0.04"/>
      </geometry>
      <surface>
        <friction>
          <ode>
            <mu>1.0</mu>
            <mu2>1.0</mu2>
          </ode>
        </friction>
      </surface>
    </collision>
  </link>

  <link name="caster">
    <inertial>
      <origin xyz="0 0 0" rpy="0 0 0"/>
      <mass value="1"/>
      <inertia ixx="0.016" ixy="0" ixz="0" iyy="0.016" iyz="0" izz="0.016"/>
    </inertial>
    <visual>
      <geometry>
        <sphere radius="0.3"/>
      </geometry>
      <material name="caster_material">
        <color rgba="0.8 0.8 0.8 1"/>
      </material>
    </visual>
    <collision>
      <geometry>
        <sphere radius="0.29"/>
      </geometry>
    </collision>
  </link>

  <link name="eyered">
    <inertial>
      <mass value="0.05"/>
      <inertia ixx="0.01" ixy="0" ixz="0" iyy="0.01" iyz="0" izz="0.01"/>
    </inertial>
    <visual>
      <geometry>
        <sphere radius="0.025"/>
      </geometry>
      <material name="eyered_material">
        <color rgba="1.0 0.0 0.0 1"/>
      </material>
    </visual>
  </link>

  <link name="eye2">
    <visual>
      <geometry>
        <sphere radius="0.025"/>
      </geometry>
    </visual>
  </link>

  <link name="side_leg_left">
    <visual>
      <geometry>
        <box size="0.2 0.1 0.5"/>
      </geometry>
      <material name="side_leg_left_material">
        <color rgba="0.3 0.4 0.8 1"/>
      </material>
    </visual>
  </link>

  <link name="side_leg_right">
    <visual>
      <geometry>
        <box size="0.2 0.1 0.5"/>
      </geometry>
      <material name="side_leg_right_material">
        <color rgba="0.3 0.4 0.8 1"/>
      </material>
    </visual>
  </link>

  <joint name="left_wheel_joint" type="continuous">
    <parent link="body"/>
    <child link="left_wheel"/>
    <origin xyz="0 0.33 -0.3" rpy="-1.5707 0 0"/>
    <axis xyz="0 1 0"/>
  </joint>

  <joint name="right_wheel_joint" type="continuous">
    <parent link="body"/>
    <child link="right_wheel"/>
    <origin xyz="0 -0.33 -0.3" rpy="-1.5707 0 0"/>
    <axis xyz="0 1 0"/>
  </joint>

  <joint name="front_wheel_joint" type="continuous">
    <parent link="body"/>
    <child link="front_wheel"/>
    <origin xyz="0.3 0 -0.3" rpy="-1.5707 0 0"/>
    <axis xyz="0 1 0"/>
  </joint>

  <joint name="caster_wheel_joint" type="fixed">
    <parent link="body"/>
    <child link="caster"/>
    <origin xyz="0 0 0.28" rpy="0.5 0 0"/>
  </joint>

  <joint name="redeye_joint" type="fixed">
    <parent link="body"/>
    <child link="eyered"/>
    <origin xyz="0.23 0.07 0.45" rpy="0 0 0"/>
  </joint>

  <joint name="eye2_joint" type="fixed">
    <parent link="body"/>
    <child link="eye2"/>
    <origin xyz="0.24 0 0.45" rpy="0 0 0"/>
  </joint>

  <joint name="side_leg_left_joint" type="fixed">
    <parent link="body"/>
    <child link="side_leg_left"/>
    <origin xyz="0 0.32 -0.07" rpy="0 0 0"/>
  </joint>

  <joint name="side_leg_right_joint" type="fixed">
    <parent link="body"/>
    <child link="side_leg_right"/>
    <origin xyz="0 -0.32 -0.07" rpy="0 0 0"/>
  </joint>

  <ros2_control name="GazeboSimSystem" type="system">
    <hardware>
      <plugin>gz_ros2_control/GazeboSimSystem</plugin>
    </hardware>

    <joint name="left_wheel_joint">
      <command_interface name="velocity">
        <param name="min">-5.0</param>
        <param name="max">5.0</param>
      </command_interface>
      <state_interface name="position"/>
      <state_interface name="velocity"/>
    </joint>

    <joint name="right_wheel_joint">
      <command_interface name="velocity">
        <param name="min">-5.0</param>
        <param name="max">5.0</param>
      </command_interface>
      <state_interface name="position"/>
      <state_interface name="velocity"/>
    </joint>
  </ros2_control>

    <gazebo>
    <plugin filename="gz_ros2_control-system" name="gz_ros2_control::GazeboSimROS2ControlPlugin">
      <parameters>$(arg config_dir)/diff_drive_controller.yaml</parameters>
    </plugin>
  </gazebo>


</robot>
